Workbook

Sheet Dissection Map
A1: Section | B1: Investigation Area | C1: Purpose / Item | D1: Sheet / Layer | E1: Cell / Range / Control | F1: Formula / Logic / Finding | G1: Status / Notes
A2: 1 | B2: Cylinder Definition / User Inputs | C2: True user-entry point | D2: OrderEntry UserForm | E2: Form | F2: The form title is "JIT 2026 Pricing Calculator". User selections are written into workbook cells and those cells drive the downstream formulas. | G2: VERIFIED from recovered OrderEntry VBA and form definition.
A3: 1 | B3: Cylinder Definition / User Inputs | C3: Customer | D3: OrderEntry -> Customer | E3: ComboBox2 -> Customer!B1 | F3: ComboBox2_Change writes the selected customer to Customer!B1. RowSource is Customer!B3:G10000. | G3: VERIFIED
A4: 1 | B4: Cylinder Definition / User Inputs | C4: Series | D4: OrderEntry -> Data | E4: ComboBox6 -> Data!B3 | F4: Series control. RowSource ShipVia!H2:H12. | G4: VERIFIED
A5: 1 | B5: Cylinder Definition / User Inputs | C5: Mount | D5: OrderEntry -> Data | E5: ComboBox5 -> Data!B5 | F5: Mount control. RowSource ShipVia!F2:F27. | G5: VERIFIED
A6: 1 | B6: Cylinder Definition / User Inputs | C6: Bore | D6: OrderEntry -> Data | E6: ComboBox11 -> Data!B4 | F6: Bore control. RowSource ShipVia!D21:D36. | G6: VERIFIED
A7: 1 | B7: Cylinder Definition / User Inputs | C7: Stroke | D7: OrderEntry -> Data | E7: TextBox22 -> likely Data!B8 | F7: Form label at the TextBox22 position is Stroke. Data!B8 is the workbook stroke input used by model and pricing formulas. | G7: STRONGLY INFERRED; direct ControlSource still to verify.
A8: 1 | B8: Cylinder Definition / User Inputs | C8: Rod | D8: OrderEntry -> Data | E8: ComboBox7 -> Data!B6 | F8: Rod control. RowSource ShipVia!K1:K6. | G8: VERIFIED
A9: 1 | B9: Cylinder Definition / User Inputs | C9: Rod Style / Thread | D9: OrderEntry -> Data | E9: ComboBox10 -> Data!D15 | F9: Form label is Style. RowSource ShipVia!D12:D16. D15 is used by model-code and rod-thread logic. | G9: VERIFIED
A10: 1 | B10: Cylinder Definition / User Inputs | C10: Cushion | D10: OrderEntry -> Data | E10: ComboBox12 -> Data!B7 | F10: Cushion control. RowSource ShipVia!E18:E24. | G10: VERIFIED
A11: 1 | B11: Cylinder Definition / User Inputs | C11: Ports | D11: OrderEntry -> Data | E11: ComboBox13 -> Data!D2 | F11: Ports control. RowSource ShipVia!E26:E29. | G11: VERIFIED
A12: 1 | B12: Cylinder Definition / User Inputs | C12: Seal | D12: OrderEntry -> Data | E12: ComboBox9 -> Data!B10 | F12: Seal control. RowSource ShipVia!D6:D11. | G12: VERIFIED
... A19: 1 | B19: Cylinder Definition / User Inputs | C19: Net Each display | D19: OrderEntry <- Data | E19: ListBox1 <- Data!D6 | F19: The form reads Data!D6 into ListBox1, labeled Net Each. This directly links the form to the central calculated cost/net value. | G19: VERIFIED
A20: 2 | B20: Model-Code Generation | C20: Model code assembly | D20: Data | E20: A1 | F20: =CONCATENATE(B3,B1,E5,B1,B4,C1,B8,C1,B6,B1,D15,B1,B7,B1,D2,B1,B10,B1,"S") | G20: VERIFIED; full Section 2 trace pending.
A21: 2 | B21: Model-Code Generation | C21: Mount/DRE model segment | D21: Data | E21: E5 | F21: =IF(D18="",B5,CONCATENATE("DRE/",B5)) | G21: VERIFIED
A22: 4 | B22: Base-Cylinder Component Cost | C22: Base component cost convergence | D22: Data | E22: C5 | F22: =H!Q52+A!Q53+MH!O52+PH!J34+IH!Q36+IMH!O27 | G22: VERIFIED
A23: 5 | B23: Stroke-Related Cost | C23: Stroke-related cost convergence | D23: Data | E23: C8 | F23: =H!W52+A!W53+MH!S52+PH!N34+IH!W36+IMH!S27 | G23: VERIFIED
A24: 6 | B24: Accessories and Adders | C24: Accessory total | D24: Data | E24: H23 | F24: =SUM(H8:H22)+H25 | G24: VERIFIED
A25: 6 | B25: Accessories and Adders | C25: Additional option total | D25: Data | E25: H33 | F25: =SUM(H26:H32) | G25: VERIFIED
A26: 8 | B26: Cost to List Price to Selling Price | C26: Central pricing convergence | D26: Data | E26: D6 | F26: Combines C5+C8+C10+H23+H33+series option sheet totals; applies (1-D4); if D18 nonblank adds C5*0.65; then adds H24 and ROUNDUP(...,0). | G26: VERIFIED
A27: 8 | B27: Cost to List Price to Selling Price | C27: List price | D27: Data | E27: I13 | F27: =D6/(1-D4) | G27: VERIFIED
A28: 9 | B28: Quote Presentation Logic | C28: Displayed list price | D28: Quote Form | E28: D11 | F28: =IF(Data!B3="W",Data!I13*0.85,Data!I13) | G28: VERIFIED
A29: 9 | B29: Quote Presentation Logic | C29: Standard sell price | D29: Quote Form | E29: F11 | F29: =D11*(1-E11) | G29: VERIFIED
A30: 9 | B30: Quote Presentation Logic | C30: Expedited price | D30: Quote Form | E30: F12 | F30: =IF(F11="","",IF(F11>1000,F11*1.3,F11*1.4)) | G30: VERIFIED
A31: 9 | B31: Quote Presentation Logic | C31: Emergency price | D31: Quote Form | E31: F13 | F31: =F12*1.25 | G31: VERIFIED
A32: 10 | B32: VBA Workflow | C32: Quote button workflow | D32: OrderEntry VBA | E32: CommandButton2_Click | F32: On Quote, VBA copies/sorts option selections, transfers selected option lines to Quote Form, restores quote formulas, updates ShipVia helper data, then returns to Quote Form. | G32: VERIFIED; detailed workflow deferred to Section 10.
A33: 3 | B33: Series Routing | C33: Section placeholder | G33: PENDING
A34: 7 | B34: Special-Order Pricing Rules | C34: Section placeholder | G34: PENDING
A35: 2 | B35: Model-Code Generation | C35: Authoritative model output | D35: Data | E35: A1 | F35: =CONCATENATE(B3,B1,E5,B1,B4,C1,B8,C1,B6,B1,D15,B1,B7,B1,D2,B1,B10,B1,"S") | G35: VERIFIED - central model-code constructor
A36: 2 | B36: Model-Code Generation | C36: Series segment | D36: OrderEntry -> Data | E36: Series -> Data!B3 | F36: Data!B3 is first segment of Data!A1. | G36: VERIFIED
A37: 2 | B37: Model-Code Generation | C37: Mount segment | D37: OrderEntry -> Data | E37: Mount -> Data!B5 -> Data!E5 | F37: E5 uses B5 normally; when D18 is populated it becomes "DRE/" & B5. | G37: VERIFIED
A38: 2 | B38: Model-Code Generation | C38: Bore segment | D38: OrderEntry -> Data | E38: Bore -> Data!B4 | F38: Inserted directly into A1. | G38: VERIFIED
A39: 2 | B39: Model-Code Generation | C39: Stroke segment | D39: OrderEntry -> Data | E39: Stroke -> Data!B8 | F39: Inserted directly into A1 between x separators. | G39: VERIFIED model dependency; Section 1 direct form control mapping still pending
A40: 2 | B40: Model-Code Generation | C40: Rod segment | D40: OrderEntry -> Data | E40: Rod -> Data!B6 | F40: Inserted directly into A1. | G40: VERIFIED
A41: 2 | B41: Model-Code Generation | C41: Rod-style segment | D41: OrderEntry -> Data | E41: Style -> Data!D15 | F41: Inserted directly into A1; D23 is description only. | G41: VERIFIED
A42: 2 | B42: Model-Code Generation | C42: Cushion segment | D42: OrderEntry -> Data | E42: Cushion -> Data!B7 | F42: Inserted directly into A1; D28 is description only. | G42: VERIFIED
A43: 2 | B43: Model-Code Generation | C43: Ports segment | D43: OrderEntry -> Data | E43: Ports -> Data!D2 | F43: Inserted directly into A1. | G43: VERIFIED
A44: 2 | B44: Model-Code Generation | C44: Seal segment | D44: OrderEntry -> Data | E44: Seal -> Data!B10 | F44: Inserted directly into A1; D30 is description only. | G44: VERIFIED
A45: 2 | B45: Model-Code Generation | C45: Model separators | D45: Data | E45: B1 / C1 | F45: B1="-"; C1="x". | G45: VERIFIED
A46: 2 | B46: Model-Code Generation | C46: Fixed suffix | D46: Data | E46: A1 literal | F46: Model always appends "-S" through B1 then literal "S". | G46: VERIFIED
...
